Workbook
Name tar_dur_1: 'Input Data'!$G$11
Name retirement_yr: Model!$C$220
Name dn_nw_10y: Model!$N$58
Name isa_limit: Model!$C$474
Name ann_rent_yield_2: 'Input Data'!$C$63
Name tar_amount_2: 'Input Data'!$E$13
Name tar_savings_2: 'Input Data'!$I$13
Name pa_tax_lb: 'Input Data'!$C$89
Name hal_mor_mp: 'Input Data'!$M$47
Name tar_date_2: 'Input Data'!$D$13
Name psy_fas: 'Input Data'!$F$41
Name tar_amount_3: 'Input Data'!$E$12
Name psy_rdm: 'Input Data'!$F$39
Name rent_util_2: 'Input Data'!$D$63
Name pens_ann_inc_gro: Model!$C$390
Name pa_tax_ub: 'Input Data'!$D$89
Name inv_lump_pct: Model!$C$431
Name year_birth: 'Input Data'!$B$2
Name edu_level: 'Input Data'!$B$7
Name hmrc_rate: 'Input Data'!$C$72
Name liv_sit: 'Input Data'!$B$4
Name rent_util_3: 'Input Data'!$D$64
Name ann_payment: Model!$C$135
Name br_tax_ub: 'Input Data'!$D$90
Name mon_debt_ir_1: #REF!
Name mon_payment_1: Model!$C$136
Name ann_th_salary: 'Input Data'!$E$22
Name ann_debt_ir_2: #REF!
Name uk_pen_gr: 'Input Data'!$C$70
Name mon_payment_2: #REF!
Name uk_min_wage: 'Input Data'!$C$71
Name ann_gross_sa: 'Input Data'!$C$21
Name psy_fop: 'Input Data'!$F$40
Name br_tax_lb: 'Input Data'!$C$90
Name hal_mor_apr_red: #REF!
Name tar_date_1: 'Input Data'!$D$11
Name br_tax_pct: 'Input Data'!$E$90
Name dn_nw_20y: Model!$AH$40
Name age: 'Input Data'!$B$3
Name msci_ann_div: 'Input Data'!$D$78
Name dn_nw_5y: Model!$I$58
Name hal_mor_apr: 'Input Data'!$L$47
Name ae_pen_mo: 'Input Data'!$L$39
Name down_payment: Model!$C$130
Name tar_dur_2: 'Input Data'!$G$13
Name mon_ni: 'Input Data'!$B$44
Name uk_lt_ir: 'Input Data'!$C$69
Name ann_exp: 'Input Data'!$C$37
Name ann_debt_ir_1: Model!$C$134
Name mon_exp: 'Input Data'!$B$37
Name ann_rent_yield_3: 'Input Data'!$C$64
Name hr_tax_lb: 'Input Data'!$C$91
Name tar_savings_1: 'Input Data'!$I$11
Name hous_dep: 'Input Data'!$B$5
Name ann_payment_2: #REF!
Name inv_cont_pct: Model!$C$473
Name dn_nw_bl: Model!$D$58
Name hr_tax_ub: 'Input Data'!$D$91
Name inv_bal_bl: 'Input Data'!$J$35
Name ar_tax_lb: 'Input Data'!$C$92

Sheet questionnaire_responses_rows
A1: id | B1: user_id | C1: first_name | D1: last_name | E1: email_address | F1: age_or_year_of_birth | G1: uk_location | H1: created_at | I1: updated_at | J1: current_living_situation | K1: highest_education_level | L1: living_arrangement | M1: additional_background_info | N1: current_work_situation | O1: monthly_take_home_salary | P1: other_income_sources | Q1: monthly_rent_mortgage | R1: monthly_bills_utilities | S1: monthly_transport | T1: monthly_subscriptions | U1: monthly_food_groceries | V1: monthly_leisure_entertainment | W1: monthly_other_expenses | X1: has_savings_accounts | Y1: savings_accounts | Z1: has_debts | AA1: debts | AB1: has_investment_platforms | AC1: investment_platforms | AD1: has_pension_accounts | AE1: pension_accounts | AF1: uses_tax_efficiency_methods | AG1: tax_efficiency_details | AH1: has_other_assets | AI1: other_assets | AJ1: has_automatic_plans | AK1: automatic_plans | AL1: has_emergency_fund | AM1: emergency_fund_months | AN1: emergency_fund_amount | AO1: has_dependents | AP1: dependents_details | AQ1: gross_annual_salary | AR1: net_monthly_salary | AS1: other_income_frequency | AT1: debt_total_amount | AU1: monthly_surplus | AV1: data_collection_date | AW1: monthly_rent_mortgage_numeric | AX1: monthly_bills_utilities_numeric | AY1: monthly_transport_numeric | AZ1: monthly_subscriptions_numeric | BA1: monthly_food_groceries_numeric | BB1: monthly_leisure_entertainment_numeric | BC1: monthly_other_expenses_numeric | BD1: emergency_fund_amount_numeric | BE1: country | BF1: city | BG1: investment_service_providers | BH1: other_income_amount
A2: 529278c1-e6bb-4ee4-a877-1436b5c84840 | C2: Alpha | D2: 2 | F2: 34 | H2: 2025-05-28 12:01:18.565955+00 | I2: 2025-05-28 12:01:18.565955+00 | J2: own-mortgage | K2: undergraduate | L2: live-with-family | N2: unemployed | O2: 9000 | P2: None | Q2: 817 | R2: 350 | S2: 200 | T2: 25 | U2: 900 | V2: 250 | W2: 0 | X2: no | Y2: [{"bank": "", "balance": "", "interestRate": ""}] | Z2: yes | AA2: [{"type": "mortgage", "provider": "Lloyds", "customType": "", "interestRate": "1.46", "monthlyPayment": "2220.87", "outstandingBalance": "346257"}] | AB2: yes | AC2: [{"provider": "Charles Stanley", "totalValue": "111,104", "accountType": "ISA", "monthlyContribution": "", "performanceLastYear": "1.49%"}] | AD2: yes | AE2: [{"type": "workplace", "provider": "L&G", "currentValue": "53755.57", "monthlyContribution": "0"}, {"type": "workplace", "provider": "L&G", "currentValue": "57674.1", "monthlyContribution": ""}] | AF2: yes | AI2: [] | AJ2: FALSE | AK2: [] | AO2: no | AP2: [] | AQ2: 108000 | AR2: 9000 | AT2: 0 | AU2: 6458 | AV2: 2025-05-28 12:01:17.182+00 | AW2: 817 | AX2: 350 | AY2: 200 | AZ2: 25 | BA2: 900 | BB2: 250 | BC2: 0 | BE2: England | BF2: London | BG2: [] | BH2: 0

Sheet Data
A1: Time Horizon | B1: Category | C1: Goal | D1: Calculation | E1: 1 | F1: Helpers | W1: Dates
A2: Short-Term | B2: Career & Education | C2: Launching a Venture / Franchise | D2: savings target | E2: A. | F2: {=UNIQUE(Data!A2:A1000)} -> Short-Term | G2: B. | H2: {=UNIQUE(Data!B2:B1000)} -> Career & Education | I2: C. | J2: =IFERROR(__xludf.DUMMYFUNCTION("SORT(UNIQUE(FILTER(Data!C2:C1000, (Data!B2:B1000 = 'Input Data'!B11))))"),"Buying a Car") -> Buying a Car | K2: A. | L2: {=UNIQUE(Data!A2:A1000)} -> Short-Term | M2: B. | N2: {=UNIQUE(Data!B2:B1000)} -> Career & Education | O2: C. | P2: =IFERROR(__xludf.DUMMYFUNCTION("SORT(UNIQUE(FILTER(Data!C2:C1000, (Data!B2:B1000 = 'Input Data'!B13))))"),"Building an Investment Portfolio") -> Building an Investment Portfolio | Q2: A. | R2: {=UNIQUE(Data!A2:A1000)} -> Short-Term | S2: B. | T2: {=UNIQUE(Data!B2:B1000)} -> Career & Education | U2: C. | V2: =IFERROR(__xludf.DUMMYFUNCTION("SORT(UNIQUE(FILTER(Data!C2:C1000, (Data!B2:B1000 = 'Input Data'!B12))))"),"Building a Safety Net") -> Building a Safety Net
A3: Medium-Term | B3: Career & Education | C3: Master’s Degree or Further Study | D3: savings target | F3: Medium-Term | H3: Essentials | J3: =IFERROR(__xludf.DUMMYFUNCTION("""COMPUTED_VALUE"""),"Buying a Property") -> Buying a Property | L3: Medium-Term | N3: Essentials | P3: =IFERROR(__xludf.DUMMYFUNCTION("""COMPUTED_VALUE"""),"Financial Independence (FIRE goals)") -> Financial Independence (FIRE goals) | R3: Medium-Term | T3: Essentials | V3: =IFERROR(__xludf.DUMMYFUNCTION("""COMPUTED_VALUE"""),"Paying off Loan") -> Paying off Loan
A4: Long-Term | B4: Career & Education | C4: Starting a Business (scaled-up funding) | D4: savings target | F4: Long-Term | H4: Family & Legacy | J4: =IFERROR(__xludf.DUMMYFUNCTION("""COMPUTED_VALUE"""),"Furniture or Home Decor") -> Furniture or Home Decor | L4: Long-Term | N4: Family & Legacy | P4: =IFERROR(__xludf.DUMMYFUNCTION("""COMPUTED_VALUE"""),"Pension Top-Up Plan") -> Pension Top-Up Plan | R4: Long-Term | T4: Family & Legacy | V4: =IFERROR(__xludf.DUMMYFUNCTION("""COMPUTED_VALUE"""),"Saving for a Career Break or Sabbatical") -> Saving for a Career Break or Sabbatical
A5: N/A | B5: Career & Education | C5: Professional Qualification or Certification | D5: savings target | F5: N/A | H5: Financial Stability | J5: =IFERROR(__xludf.DUMMYFUNCTION("""COMPUTED_VALUE"""),"Paying Off Mortgage Early") -> Paying Off Mortgage Early | L5: N/A | N5: Financial Stability | P5: =IFERROR(__xludf.DUMMYFUNCTION("""COMPUTED_VALUE"""),"Retirement Savings") -> Retirement Savings | R5: N/A | T5: Financial Stability
B6: Career & Education | C6: Course or Training Fees | D6: savings target | H6: Lifestyle & Leisure | J6: =IFERROR(__xludf.DUMMYFUNCTION("""COMPUTED_VALUE"""),"Saving for a House Deposit") -> Saving for a House Deposit | N6: Lifestyle & Leisure | T6: Lifestyle & Leisure
B7: Career & Education | C7: Laptop / Tools for Work | D7: savings target | H7: Property & Real Estate | N7: Property & Real Estate | T7: Property & Real Estate
B8: Career & Education | C8: Starting a Business (initial expenses) | D8: savings target | H8: N/A | N8: N/A | T8: N/A
B9: Essentials | C9: Emergency Fund | D9: savings target | H9: Retirement & Future Security | N9: Retirement & Future Security | T9: Retirement & Future Security
B10: Essentials | C10: Rent Deposit / Moving Costs | D10: savings target
B11: Essentials | C11: Paying off Credit Card Debt
B12: Essentials | C12: Paying off Buy Now Pay Later (BNPL)
B13: Essentials | C13: Paying off Overdraft
B14: Essentials | C14: Covering Annual Bills | D14: savings target
B15: Family & Legacy | C15: Child’s Education Fund
B16: Family & Legacy | C16: Childcare Savings
B17: Family & Legacy | C17: Inheritance Planning
B18: Family & Legacy | C18: Philanthropy / Charity Fund
B19: Family & Legacy | C19: Wedding Fund
B20: Family & Legacy | C20: IVF or Fertility Treatment
B21: Family & Legacy | C21: Having a Baby (preparation costs)
B22: Family & Legacy | C22: Supporting a Partner or Relative
B23: Financial Stability | C23: Paying off Loan
B24: Financial Stability | C24: Building a Safety Net
B25: Financial Stability | C25: Saving for a Career Break or Sabbatical
B26: Lifestyle & Leisure | C26: Extended Travel / Gap Year
... B41: Retirement & Future Security | C41: Building an Investment Portfolio

Sheet Input Data
A1: Customer data
A2: Year of birth | B2: =if(questionnaire_responses_rows!F2 >1000,questionnaire_responses_rows!F2,-(questionnaire_responses_rows!F2-year(today()))) -> 1991 | C2: =B2+70 -> 2061 | D2: =C2-2025 -> 36
A3: Age | B3: =if(questionnaire_responses_rows!F2 <1000,questionnaire_responses_rows!F2,year(today())-questionnaire_responses_rows!F2) -> 34
A4: Living situation | B4: =questionnaire_responses_rows!L2 -> live-with-family
A5: Household Dependents? | B5: =questionnaire_responses_rows!AO2 -> no
A6: Job status | B6: =questionnaire_responses_rows!N2 -> unemployed
A7: Education level | B7: =questionnaire_responses_rows!K2 -> undergraduate
A9: Financial goals
A10: Timeline | B10: Category | C10: Goal | D10: Target Date formatted as (DD/MM/YYYY) | E10: Target total (must be a number) | F10: Target Amount Frequency | G10: Duration | I10: Savings Already Allocated | J10: Priority | K10: Additional Details (mortgage interest rate, etc.)
A11: Medium-Term | B11: Property & Real Estate | C11: Buying a Property | D11: 46023 | E11: 600000 | F11: Monthly | G11: 25 | H11: Years | I11: 0 | J11: High
A12: Short-Term | B12: Financial Stability | C12: Saving for a Career Break or Sabbatical | D12: 46022 | E12: 15800 | F12: Monthly | G12: 6 | H12: Months | I12: 0 | J12: High
A13: Long-Term | B13: Retirement & Future Security | C13: Retirement Savings | D13: 58987 | E13: 50000 | F13: Annually | G13: 36 | H13: Years | I13: 0 | J13: Medium
A16: Income & Expenses | I16: Assets & Debts
A18: Income | I18: Current & Savings accounts
A20: Income source | B20: Payment Frequency | C20: Annual Gross Salary | D20: Net Monthly Salary | E20: Annual Takehome Salary
A21: Salary | B21: Monthly | C21: =questionnaire_responses_rows!AQ2 -> 108000 | D21: =questionnaire_responses_rows!AR2 -> 9000 | E21: =D21*12 -> 108000 | I21: Account type | J21: Provider | K21: Balance | L21: Interest Rate (%) | M21: Last year dividends (%) | N21: Last year dividends (%)
A22: Additional | B22: NA | C22: 0 | D22: =sum(D21) -> 9000 | E22: =sum(E21) -> 108000 | I22: Cash/ savings account 1 | J22: =PARSEJSONDATA(questionnaire_responses_rows!Y2)
A23: Total income minus tax | I23: Cash/ savings account 2
I24: Cash/ savings account 3
I25: Cash/ savings account 4
I26: Cash/ savings account 5
A27: Expenses (monthly) | I27: Total | K27: =SUM(K22:K26) -> 0 | L27: =SUMPRODUCT(K22:K26,L22:L26)/SUM($K22:$K26) -> #DIV/0! | M27: =SUMPRODUCT($K22:$K26,M22:M26)/SUM($K22:$K26) -> #DIV/0! | N27: =SUMPRODUCT($K22:$K26,N22:N26)/SUM($K22:$K26) -> #DIV/0!
E28: Dependent Details
A29: =questionnaire_responses_rows!J2 -> own-mortgage | B29: Monthly | C29: Annual | E29: Age | F29: Relationship | G29: Financial Support | I29: Investment accounts
A30: =IF(ISNUMBER(SEARCH("mortgage", questionnaire_responses_rows!J2)), "Mortgage", "Rent") -> Mortgage | B30: =questionnaire_responses_rows!Q2 -> 817 | C30: =B30*12 -> 9804 | E30: =PARSEJSONDATA(questionnaire_responses_rows!AP2) -> #ERROR! | I30: Provider | J30: Balance | K30: Account type | L30: Monthly Contributions | M30: Last year growth rate (%) | N30: Last year dividends (%)
A31: Utilities | B31: =questionnaire_responses_rows!R2 -> 350 | C31: =B31*12 -> 4200 | I31: =PARSEJSONDATA(questionnaire_responses_rows!AC2) -> Charles Stanley | J31: 111104 | K31: ISA | M31: 1.49
A32: Transport | B32: =questionnaire_responses_rows!S2 -> 200 | C32: =B32*12 -> 2400
A33: Subscriptions | B33: =questionnaire_responses_rows!T2 -> 25 | C33: =B33*12 -> 300
A34: Food and Groceries | B34: =questionnaire_responses_rows!U2 -> 900 | C34: =B34*12 -> 10800
A35: Leisure and Entertainment | B35: =questionnaire_responses_rows!V2 -> 250 | C35: =B35*12 -> 3000 | I35: Total | J35: =SUM(J28:J34) -> 111104 | L35: =SUM(L30:L34) -> 0
A36: Other regular expenses | B36: =questionnaire_responses_rows!W2 -> 0 | C36: =B36*12 -> 0
A37: Total expenses | B37: =sum(B30:B36) -> 2542 | C37: =B37*12 -> 30504 | E37: Psychographic assessment | I37: Pension accounts
E38: Indicator | F38: Score (/5) | I38: Account type | J38: Provider | K38: Balance | L38: Monthly Contributions | M38: Last year growth rate (%) | N38: Last year dividends (%)
E39: Risk & Decision-making | F39: 3.68 | I39: =PARSEJSONDATA(questionnaire_responses_rows!AE2) -> workplace | J39: L&G | K39: 53755.57 | L39: 0
E40: Future Orientation & Planning | F40: 5 | I40: workplace | J40: L&G | K40: 57674.1
E41: Financial Awareness & Stability | F41: 4.13
B43: Monthly | C43: Annual | I43: Total | K43: =SUM(K36:K42) -> 111429.67 | L43: =SUM(L38:L42) -> 0
A44: Net income | B44: =D22-B37 -> 6458 | C44: =B44*12 -> 77496
I45: Debts
E46: Property Estimation Tool | I46: Debt type | J46: Provider | K46: Custom Type | L46: APR (%) | M46: Monthly payment | N46: Outstanding balance
...

Sheet Model
A1: 0 | B1: Do-Nothing Scenario
B3: Assumptions | C3: No changes are made to income/expenses
C4: Goals are not yet considered
B7: Net income by year
B9: Income | C9: Interest/ growth rates | D9: Baseline June 2025 | E9: 46143 | F9: 46508 | G9: 46874 | H9: 47239 | I9: 47604 | J9: 47969 | K9: 48335 | L9: 48700 | M9: 49065 | N9: 49430 | O9: 49796 | P9: 50161 | Q9: 50526 | R9: 50891 | S9: 51257 | T9: 51622 | U9: 51987 | V9: 52352 | W9: 52718 | X9: 53083 | Y9: 53448 | Z9: 53813 | AA9: 54179 | AB9: 54544 | AC9: 54909 | AD9: 55274 | AE9: 55640 | AF9: 56005 | AG9: 56370 | AH9: 56735 | AI9: 57101 | AJ9: 57466 | AK9: 57831 | AL9: 58196 | AM9: 58562 | AN9: 58927 | AO9: 59292 | AP9: 59657 | AQ9: 60023 | AR9: 60388 | AS9: 60753 | AT9: 61118 | AU9: 61484 | AV9: 61849 | AW9: 62214 | AX9: 62579 | AY9: 62945 | AZ9: 63310
B10: Total take home salary | C10: 0 | D10: 54000 | E10: =ann_th_salary -> 108000 | F10: =ann_th_salary -> 108000 | G10: =ann_th_salary -> 108000 | H10: =ann_th_salary -> 108000 | I10: =ann_th_salary -> 108000 | J10: =ann_th_salary -> 108000 | K10: =ann_th_salary -> 108000 | L10: =ann_th_salary -> 108000 | ... AZ10: =ann_th_salary -> 108000
B11: Total dividend income | C11: 0 | D11: =D33*$C11 -> 0 | E11: =E33*$C11 -> 0 | F11: =F33*$C11 -> 0 | G11: =G33*$C11 -> 0 | H11: =H33*$C11 -> 0 | I11: =I33*$C11 -> 0 | J11: =J33*$C11 -> 0 | K11: =K33*$C11 -> 0 | ... AZ11: =AZ33*$C11 -> 0
B12: Total expenses (inc. mortgage) | C12: 0 | D12: =ann_exp+('Input Data'!$M$52*12) -> 57154.44 | E12: =ann_exp+('Input Data'!$M$52*12) -> 57154.44 | F12: =ann_exp+('Input Data'!$M$52*12) -> 57154.44 | G12: =ann_exp+('Input Data'!$M$52*12) -> 57154.44 | H12: =ann_exp+('Input Data'!$M$52*12) -> 57154.44 | I12: =ann_exp+('Input Data'!$M$52*12) -> 57154.44 | J12: =ann_exp+('Input Data'!$M$52*12) -> 57154.44 | K12: =ann_exp+('Input Data'!$M$52*12) -> 57154.44 | ... AZ12: =ann_exp+('Input Data'!$M$52*12) -> 57154.44
B13: Expenses % salary | D13: =iferror(D12/D10,"N/A") -> 1.0584156 | E13: =iferror(E12/E10,"N/A") -> 0.52920778 | F13: =iferror(F12/F10,"N/A") -> 0.52920778 | G13: =iferror(G12/G10,"N/A") -> 0.52920778 | H13: =iferror(H12/H10,"N/A") -> 0.52920778 | I13: =iferror(I12/I10,"N/A") -> 0.52920778 | J13: =iferror(J12/J10,"N/A") -> 0.52920778 | K13: =iferror(K12/K10,"N/A") -> 0.52920778 | ... AZ13: =iferror(AZ12/AZ10,"N/A") -> 0.52920778
B14: Net income | D14: =sum(D10:D11)-D12 -> -3154.44 | E14: =sum(E10:E11)-E12 -> 50845.56 | F14: =sum(F10:F11)-F12 -> 50845.56 | G14: =sum(G10:G11)-G12 -> 50845.56 | H14: =sum(H10:H11)-H12 -> 50845.56 | I14: =sum(I10:I11)-I12 -> 50845.56 | J14: =sum(J10:J11)-J12 -> 50845.56 | K14: =sum(K10:K11)-K12 -> 50845.56 | ... AZ14: =sum(AZ10:AZ11)-AZ12 -> 50845.56
B15: Income allocation to savings | C15: 1 | D15: =$C15*D$14 -> -3154.44 | E15: =$C15*E$14 -> 50845.56 | F15: =$C15*F$14 -> 50845.56 | G15: =$C15*G$14 -> 50845.56 | H15: =$C15*H$14 -> 50845.56 | I15: =$C15*I$14 -> 50845.56 | J15: =$C15*J$14 -> 50845.56 | K15: =$C15*K$14 -> 50845.56 | ... AZ15: =$C15*AZ$14 -> 50845.56
B16: Income allocation to investments | C16: 0 | D16: =$C16*D$15 -> 0 | E16: =$C16*E$15 -> 0 | F16: =$C16*F$15 -> 0 | G16: =$C16*G$15 -> 0 | H16: =$C16*H$15 -> 0 | I16: =$C16*I$15 -> 0 | J16: =$C16*J$15 -> 0 | K16: =$C16*K$15 -> 0 | ... AZ16: =$C16*AZ$15 -> 0
B18: Net wealth by year
B20: Assets | C20: Interest/ growth rates | D20: Baseline June 2025 | E20: 46143 | F20: 46508 | G20: 46874 | H20: 47239 | I20: 47604 | J20: 47969 | K20: 48335 | L20: 48700 | M20: 49065 | N20: 49430 | O20: 49796 | P20: 50161 | Q20: 50526 | R20: 50891 | S20: 51257 | T20: 51622 | U20: 51987 | V20: 52352 | W20: 52718 | X20: 53083 | Y20: 53448 | Z20: 53813 | AA20: 54179 | AB20: 54544 | AC20: 54909 | AD20: 55274 | AE20: 55640 | AF20: 56005 | AG20: 56370 | AH20: 56735 | AI20: 57101 | AJ20: 57466 | AK20: 57831 | AL20: 58196 | AM20: 58562 | AN20: 58927 | AO20: 59292 | AP20: 59657 | AQ20: 60023 | AR20: 60388 | AS20: 60753 | AT20: 61118 | AU20: 61484 | AV20: 61849 | AW20: 62214 | AX20: 62579 | AY20: 62945 | AZ20: 63310
B21: Cash/ savings accounts
B22: Account 1 | C22: ='Input Data'!L22 | D22: ='Input Data'!K22 | E22: =D22*(1+$C22)+D14*$C$15 -> -3154.44 | F22: =E22*(1+$C22)+E14*$C$15 -> 47691.12 | G22: =F22*(1+$C22)+F14*$C$15 -> 98536.68 | H22: =G22*(1+$C22)+G14*$C$15 -> 149382.24 | I22: =H22*(1+$C22)+H14*$C$15 -> 200227.8 | J22: =I22*(1+$C22)+I14*$C$15 -> 251073.36 | K22: =J22*(1+$C22)+J14*$C$15 -> 301918.92 | L22: =K22*(1+$C22)+K14*$C$15 -> 352764.48 | ... AZ22: =AY22*(1+$C22)+AY14*$C$15 -> 2386586.9
B23: Account 2 | C23: ='Input Data'!L23 | D23: ='Input Data'!K23 | E23: =D23*(1+$C23) -> 0 | F23: =E23*(1+$C23) -> 0 | G23: =F23*(1+$C23) -> 0 | H23: =G23*(1+$C23) -> 0 | I23: =H23*(1+$C23) -> 0 | J23: =I23*(1+$C23) -> 0 | K23: =J23*(1+$C23) -> 0 | L23: =K23*(1+$C23) -> 0 | ... AZ23: =AY23*(1+$C23) -> 0
B24: Account 3 | C24: ='Input Data'!L24 | D24: ='Input Data'!K24 | E24: =D24*(1+$C24) -> 0 | F24: =E24*(1+$C24) -> 0 | G24: =F24*(1+$C24) -> 0 | H24: =G24*(1+$C24) -> 0 | I24: =H24*(1+$C24) -> 0 | J24: =I24*(1+$C24) -> 0 | K24: =J24*(1+$C24) -> 0 | L24: =K24*(1+$C24) -> 0 | ... AZ24: =AY24*(1+$C24) -> 0
B25: Account 4 | C25: ='Input Data'!L25 | D25: ='Input Data'!K25 | E25: =D25*(1+$C25) -> 0 | F25: =E25*(1+$C25) -> 0 | G25: =F25*(1+$C25) -> 0 | H25: =G25*(1+$C25) -> 0 | I25: =H25*(1+$C25) -> 0 | J25: =I25*(1+$C25) -> 0 | K25: =J25*(1+$C25) -> 0 | L25: =K25*(1+$C25) -> 0 | ... AZ25: =AY25*(1+$C25) -> 0
B26: Account 5 | C26: ='Input Data'!L26 | D26: ='Input Data'!K26 | E26: =D26*(1+$C26) -> 0 | F26: =E26*(1+$C26) -> 0 | G26: =F26*(1+$C26) -> 0 | H26: =G26*(1+$C26) -> 0 | I26: =H26*(1+$C26) -> 0 | J26: =I26*(1+$C26) -> 0 | K26: =J26*(1+$C26) -> 0 | L26: =K26*(1+$C26) -> 0 | ... AZ26: =AY26*(1+$C26) -> 0
B27: Cash/ savings total | C27: =iferror(sumproduct(C22:C26,D22:D26)/D27,"N/A") -> N/A | D27: =subtotal(9,D22:D26) -> 0 | E27: =subtotal(9,E22:E26) -> -3154.44 | F27: =subtotal(9,F22:F26) -> 47691.12 | G27: =subtotal(9,G22:G26) -> 98536.68 | H27: =subtotal(9,H22:H26) -> 149382.24 | I27: =subtotal(9,I22:I26) -> 200227.8 | J27: =subtotal(9,J22:J26) -> 251073.36 | K27: =subtotal(9,K22:K26) -> 301918.92 | ... AZ27: =subtotal(9,AZ22:AZ26) -> 2386586.9
B28: Investment accounts
B29: ='Input Data'!I31 -> Charles Stanley | C29: =msci_ann_gr -> 0.0717 | D29: ='Input Data'!J31 -> 111104 | E29: =D29*(1+$C29)+'Input Data'!$L31 -> 119070.16 | F29: =E29*(1+$C29)+'Input Data'!$L31 -> 127607.49 | G29: =F29*(1+$C29)+'Input Data'!$L31 -> 136756.94 | H29: =G29*(1+$C29)+'Input Data'!$L31 -> 146562.42 | I29: =H29*(1+$C29)+'Input Data'!$L31 -> 157070.94 | J29: =I29*(1+$C29)+'Input Data'!$L31 -> 168332.93 | K29: =J29*(1+$C29)+'Input Data'!$L31 -> 180402.4 | L29: =K29*(1+$C29)+'Input Data'!$L31 -> 193337.25 | ... AZ29: =AY29*(1+$C29)+'Input Data'!$L31 -> 3084926.1
B30: ='Input Data'!I32 | C30: =msci_ann_gr -> 0.0717 | E30: =D30*(1+$C30)+'Input Data'!$L32 -> 0 | F30: =E30*(1+$C30)+'Input Data'!$L32 -> 0 | G30: =F30*(1+$C30)+'Input Data'!$L32 -> 0 | H30: =G30*(1+$C30)+'Input Data'!$L32 -> 0 | I30: =H30*(1+$C30)+'Input Data'!$L32 -> 0 | J30: =I30*(1+$C30)+'Input Data'!$L32 -> 0 | K30: =J30*(1+$C30)+'Input Data'!$L32 -> 0 | L30: =K30*(1+$C30)+'Input Data'!$L32 -> 0 | ... AZ30: =AY30*(1+$C30)+'Input Data'!$L32 -> 0
B31: ='Input Data'!I33 | C31: =msci_ann_gr -> 0.0717 | E31: =D31*(1+$C31)+'Input Data'!$L33 -> 0 | F31: =E31*(1+$C31)+'Input Data'!$L33 -> 0 | G31: =F31*(1+$C31)+'Input Data'!$L33 -> 0 | H31: =G31*(1+$C31)+'Input Data'!$L33 -> 0 | I31: =H31*(1+$C31)+'Input Data'!$L33 -> 0 | J31: =I31*(1+$C31)+'Input Data'!$L33 -> 0 | K31: =J31*(1+$C31)+'Input Data'!$L33 -> 0 | L31: =K31*(1+$C31)+'Input Data'!$L33 -> 0 | ... AZ31: =AY31*(1+$C31)+'Input Data'!$L33 -> 0
B32: ='Input Data'!I34 | C32: =msci_ann_gr -> 0.0717 | E32: =D32*(1+$C32)+'Input Data'!$L34 -> 0 | F32: =E32*(1+$C32)+'Input Data'!$L34 -> 0 | G32: =F32*(1+$C32)+'Input Data'!$L34 -> 0 | H32: =G32*(1+$C32)+'Input Data'!$L34 -> 0 | I32: =H32*(1+$C32)+'Input Data'!$L34 -> 0 | J32: =I32*(1+$C32)+'Input Data'!$L34 -> 0 | K32: =J32*(1+$C32)+'Input Data'!$L34 -> 0 | L32: =K32*(1+$C32)+'Input Data'!$L34 -> 0 | ... AZ32: =AY32*(1+$C32)+'Input Data'!$L34 -> 0
B33: Investments total | C33: =AVERAGE(C29:C32) -> 0.0717 | D33: =subtotal(9,D29:D32) -> 111104 | E33: =subtotal(9,E29:E32) -> 119070.16 | F33: =subtotal(9,F29:F32) -> 127607.49 | G33: =subtotal(9,G29:G32) -> 136756.94 | H33: =subtotal(9,H29:H32) -> 146562.42 | I33: =subtotal(9,I29:I32) -> 157070.94 | J33: =subtotal(9,J29:J32) -> 168332.93 | K33: =subtotal(9,K29:K32) -> 180402.4 | ... AZ33: =subtotal(9,AZ29:AZ32) -> 3084926.1
B34: Pension accounts
B35: ='Input Data'!J39 -> L&G | C35: =msci_ann_gr -> 0.0717 | D35: ='Input Data'!K39 -> 53755.57 | E35: =D35*(1+$C35)+'Input Data'!$L39 -> 57609.844 | F35: =E35*(1+$C35)+'Input Data'!$L39 -> 61740.47 | G35: =F35*(1+$C35)+'Input Data'!$L39 -> 66167.262 | H35: =G35*(1+$C35)+'Input Data'!$L39 -> 70911.455 | I35: =H35*(1+$C35)+'Input Data'!$L39 -> 75995.806 | J35: =I35*(1+$C35)+'Input Data'!$L39 -> 81444.705 | K35: =J35*(1+$C35)+'Input Data'!$L39 -> 87284.291 | L35: =K35*(1+$C35)+'Input Data'!$L39 -> 93542.574 | ... AZ35: =AY35*(1+$C35)+'Input Data'!$L39 -> 1492583.2
B36: ='Input Data'!J40 -> L&G | C36: =msci_ann_gr -> 0.0717 | D36: ='Input Data'!K40 -> 57674.1 | E36: =D36*(1+$C36)+'Input Data'!$L40 -> 61809.333 | F36: =E36*(1+$C36)+'Input Data'!$L40 -> 66241.062 | G36: =F36*(1+$C36)+'Input Data'!$L40 -> 70990.546 | H36: =G36*(1+$C36)+'Input Data'!$L40 -> 76080.568 | I36: =H36*(1+$C36)+'Input Data'!$L40 -> 81535.545 | J36: =I36*(1+$C36)+'Input Data'!$L40 -> 87381.644 | K36: =J36*(1+$C36)+'Input Data'!$L40 -> 93646.908 | L36: =K36*(1+$C36)+'Input Data'!$L40 -> 100361.39 | ... AZ36: =AY36*(1+$C36)+'Input Data'!$L40 -> 1601385.5
B37: ='Input Data'!J41 | C37: =msci_ann_gr -> 0.0717 | D37: ='Input Data'!K41 | E37: =D37*(1+C37)+'Input Data'!$L41 -> 0 | F37: =E37*(1+$C37)+'Input Data'!$L41 -> 0 | G37: =F37*(1+$C37)+'Input Data'!$L41 -> 0 | H37: =G37*(1+$C37)+'Input Data'!$L41 -> 0 | I37: =H37*(1+$C37)+'Input Data'!$L41 -> 0 | J37: =I37*(1+$C37)+'Input Data'!$L41 -> 0 | K37: =J37*(1+$C37)+'Input Data'!$L41 -> 0 | L37: =K37*(1+$C37)+'Input Data'!$L41 -> 0 | M37: =L37*(1+$C37)+'Input Data'!$L41 -> 0 | ... AZ37: =AY37*(1+$C37)+'Input Data'!$L41 -> 0
B38: ='Input Data'!J42 | C38: =msci_ann_gr -> 0.0717 | D38: ='Input Data'!K42 | E38: =D38*(1+C38)+'Input Data'!$L42 -> 0 | F38: =E38*(1+$C38)+'Input Data'!$L42 -> 0 | G38: =F38*(1+$C38)+'Input Data'!$L42 -> 0 | H38: =G38*(1+$C38)+'Input Data'!$L42 -> 0 | I38: =H38*(1+$C38)+'Input Data'!$L42 -> 0 | J38: =I38*(1+$C38)+'Input Data'!$L42 -> 0 | K38: =J38*(1+$C38)+'Input Data'!$L42 -> 0 | L38: =K38*(1+$C38)+'Input Data'!$L42 -> 0 | M38: =L38*(1+$C38)+'Input Data'!$L42 -> 0 | ... AZ38: =AY38*(1+$C38)+'Input Data'!$L42 -> 0
B39: Pensions total | D39: =subtotal(9,D35:D38) -> 111429.67 | E39: =subtotal(9,E35:E38) -> 119419.18 | F39: =subtotal(9,F35:F38) -> 127981.53 | G39: =subtotal(9,G35:G38) -> 137157.81 | H39: =subtotal(9,H35:H38) -> 146992.02 | I39: =subtotal(9,I35:I38) -> 157531.35 | J39: =subtotal(9,J35:J38) -> 168826.35 | K39: =subtotal(9,K35:K38) -> 180931.2 | ... AZ39: =subtotal(9,AZ35:AZ38) -> 3093968.7
B40: Liquid Assets Total | D40: =D27+D33+D39 -> 222533.67 | E40: =E27+E33+E39 -> 235334.89 | F40: =F27+F33+F39 -> 303280.14 | G40: =G27+G33+G39 -> 372451.43 | H40: =H27+H33+H39 -> 442936.68 | I40: =I27+I33+I39 -> 514830.09 | J40: =J27+J33+J39 -> 588232.64 | K40: =K27+K33+K39 -> 663252.52 | ... AZ40: =AZ27+AZ33+AZ39 -> 8565481.7
B41: Other assets
B45: Other assets total | D45: =subtotal(9,D42:D44) -> 0 | E45: =subtotal(9,E42:E44) -> 0 | F45: =subtotal(9,F42:F44) -> 0 | G45: =subtotal(9,G42:G44) -> 0 | H45: =subtotal(9,H42:H44) -> 0 | I45: =subtotal(9,I42:I44) -> 0 | J45: =subtotal(9,J42:J44) -> 0 | K45: =subtotal(9,K42:K44) -> 0 | ... AZ45: =subtotal(9,AZ42:AZ44) -> 0
B46: Assets Total | D46: =D27+D33+D39+D45 -> 222533.67 | E46: =E27+E33+E39+E45 -> 235334.89 | F46: =F27+F33+F39+F45 -> 303280.14 | G46: =G27+G33+G39+G45 -> 372451.43 | H46: =H27+H33+H39+H45 -> 442936.68 | I46: =I27+I33+I39+I45 -> 514830.09 | J46: =J27+J33+J39+J45 -> 588232.64 | K46: =K27+K33+K39+K45 -> 663252.52 | ... AZ46: =AZ27+AZ33+AZ39+AZ45 -> 8565481.7
B49: Debts | C49: Interest/ growth rates | D49: Baseline June 2025 | E49: 46143 | F49: 46508 | G49: 46874 | H49: 47239 | I49: 47604 | J49: 47969 | K49: 48335 | L49: 48700 | M49: 49065 | N49: 49430 | O49: 49796 | P49: 50161 | Q49: 50526 | R49: 50891 | S49: 51257 | T49: 51622 | U49: 51987 | V49: 52352 | W49: 52718 | X49: 53083 | Y49: 53448 | Z49: 53813 | AA49: 54179 | AB49: 54544 | AC49: 54909 | AD49: 55274 | AE49: 55640 | AF49: 56005 | AG49: 56370 | AH49: 56735 | AI49: 57101 | AJ49: 57466 | AK49: 57831 | AL49: 58196 | AM49: 58562 | AN49: 58927 | AO49: 59292 | AP49: 59657 | AQ49: 60023 | AR49: 60388 | AS49: 60753 | AT49: 61118 | AU49: 61484 | AV49: 61849 | AW49: 62214 | AX49: 62579 | AY49: 62945 | AZ49: 63310
B50: Cash/ savings accounts
B51: ='Input Data'!I47 -> mortgage | C51: ='Input Data'!L47/100 -> 0.0146 | D51: =-'Input Data'!N47 -> -346257 | E51: =if(FV(($C$51/12),12,'Input Data'!$M47,D51)>0,-FV(($C$51/12),12,'Input Data'!$M47,D51),0) -> -324516.82 | F51: =if(FV(($C$51/12),12,'Input Data'!$M47,E51)>0,-FV(($C$51/12),12,'Input Data'!$M47,E51),0) -> -302457.1 | G51: =if(FV(($C$51/12),12,'Input Data'!$M47,F51)>0,-FV(($C$51/12),12,'Input Data'!$M47,F51),0) -> -280073.14 | H51: =if(FV(($C$51/12),12,'Input Data'!$M47,G51)>0,-FV(($C$51/12),12,'Input Data'!$M47,G51),0) -> -257360.18 | I51: =if(FV(($C$51/12),12,'Input Data'!$M47,H51)>0,-FV(($C$51/12),12,'Input Data'!$M47,H51),0) -> -234313.38 | J51: =if(FV(($C$51/12),12,'Input Data'!$M47,I51)>0,-FV(($C$51/12),12,'Input Data'!$M47,I51),0) -> -210927.84 | K51: =if(FV(($C$51/12),12,'Input Data'!$M47,J51)>0,-FV(($C$51/12),12,'Input Data'!$M47,J51),0) -> -187198.58 | L51: =if(FV(($C$51/12),12,'Input Data'!$M47,K51)>0,-FV(($C$51/12),12,'Input Data'!$M47,K51),0) -> -163120.54 | ... AZ51: =if(FV(($C$51/12),12,'Input Data'!$M47,AY51)>0,-FV(($C$51/12),12,'Input Data'!$M47,AY51),0) -> 0
...

Sheet Summary
B1: Net income trajectory
C3: =Model!E9 -> 46143 | D3: =Model!F9 -> 46508 | E3: =Model!G9 -> 46874 | F3: =Model!H9 -> 47239 | G3: =Model!I9 -> 47604 | H3: =Model!J9 -> 47969 | I3: =Model!K9 -> 48335 | J3: =Model!L9 -> 48700 | ... AX3: =Model!AZ9 -> 63310
B4: Do-Nothing (Baseline) | C4: =Model!E14 -> 50845.56 | D4: =Model!F14 -> 50845.56 | E4: =Model!G14 -> 50845.56 | F4: =Model!H14 -> 50845.56 | G4: =Model!I14 -> 50845.56 | H4: =Model!J14 -> 50845.56 | I4: =Model!K14 -> 50845.56 | J4: =Model!L14 -> 50845.56 | ... AX4: =Model!AZ14 -> 50845.56
B5: =Model!B119 -> Meet Financial Goal: Purchasing NE London Property | C5: =Model!E149 -> -33976.56 | D5: =Model!F149 -> -33976.56 | E5: =Model!G149 -> -33976.56 | F5: =Model!H149 -> -33976.56 | G5: =Model!I149 -> -33976.56 | H5: =Model!J149 -> -33976.56 | I5: =Model!K149 -> -33976.56 | J5: =Model!L149 -> -33976.56 | ... AX5: =Model!AZ149 -> 0
B6: =Model!B167 -> Meet Financial Goal: Short Term Expenses | C6: =Model!E190 -> 0 | D6: =Model!F190 -> 0 | E6: =Model!G190 -> 0 | F6: =Model!H190 -> 0 | G6: =Model!I190 -> 0 | H6: =Model!J190 -> 0 | I6: =Model!K190 -> 0 | J6: =Model!L190 -> 0 | ... AX6: =Model!AZ190 -> 0
B7: =Model!B204 -> Meet Financial Goal: Comfortable Retirement | C7: =Model!E229 -> -15315.395 | D7: =Model!F229 -> -15315.395 | E7: =Model!G229 -> -15315.395 | F7: =Model!H229 -> -15315.395 | G7: =Model!I229 -> -15315.395 | H7: =Model!J229 -> -15315.395 | I7: =Model!K229 -> -15315.395 | J7: =Model!L229 -> -15315.395 | ... AX7: =Model!AZ229 -> 50000
B8: Meeting goals cash flow | C8: =sum(C4:C7) -> 1553.6052 | D8: =sum(D4:D7) -> 1553.6052 | E8: =sum(E4:E7) -> 1553.6052 | F8: =sum(F4:F7) -> 1553.6052 | G8: =sum(G4:G7) -> 1553.6052 | H8: =sum(H4:H7) -> 1553.6052 | I8: =sum(I4:I7) -> 1553.6052 | J8: =sum(J4:J7) -> 1553.6052 | ... AX8: =sum(AX4:AX7) -> 100845.56
B9: A. Increasing Salary | C9: =Model!E261 -> 2160 | D9: =Model!F261 -> 2203.2 | E9: =Model!G261 -> 2247.264 | F9: =Model!H261 -> 2292.2093 | G9: =Model!I261 -> 2338.0535 | H9: =Model!J261 -> 2384.8145 | I9: =Model!K261 -> 2432.5108 | J9: =Model!L261 -> 2481.161 | ... AX9: =Model!AZ261 -> 0
B10: B. Side hustles and additional income streams | C10: =Model!E291 -> 0 | D10: =Model!F291 -> 0 | E10: =Model!G291 -> 0 | F10: =Model!H291 -> 0 | G10: =Model!I291 -> 0 | H10: =Model!J291 -> 0 | I10: =Model!K291 -> 0 | J10: =Model!L291 -> 0 | ... AX10: =Model!AZ291 -> 0
B11: C. Reducing Fixed Expenses | C11: =Model!E325 -> 2070 | D11: =Model!F325 -> 2070 | E11: =Model!G325 -> 2070 | F11: =Model!H325 -> 2070 | G11: =Model!I325 -> 2070 | H11: =Model!J325 -> 2070 | I11: =Model!K325 -> 2070 | J11: =Model!L325 -> 2070 | ... AX11: =Model!AZ325 -> 2070
B12: Independent levers cash flow | C12: =SUBTOTAL(9, C9:C11) -> 4230 | D12: =SUBTOTAL(9, D9:D11) -> 4273.2 | E12: =SUBTOTAL(9, E9:E11) -> 4317.264 | F12: =SUBTOTAL(9, F9:F11) -> 4362.2093 | G12: =SUBTOTAL(9, G9:G11) -> 4408.0535 | H12: =SUBTOTAL(9, H9:H11) -> 4454.8145 | I12: =SUBTOTAL(9, I9:I11) -> 4502.5108 | J12: =SUBTOTAL(9, J9:J11) -> 4551.161 | ... AX12: =SUBTOTAL(9, AX9:AX11) -> 2070
B13: Cash flow after independent levers | C13: =SUM(C8:C11) -> 5783.6052 | D13: =SUM(D8:D11) -> 5826.8052 | E13: =SUM(E8:E11) -> 5870.8692 | F13: =SUM(F8:F11) -> 5915.8145 | G13: =SUM(G8:G11) -> 5961.6587 | H13: =SUM(H8:H11) -> 6008.4198 | I13: =SUM(I8:I11) -> 6056.1161 | J13: =SUM(J8:J11) -> 6104.7663 | ... AX13: =SUM(AX8:AX11) -> 102915.56
B14: D. Investing in higher-yield savings | C14: 0 | D14: 0 | E14: 0 | F14: 0 | G14: 0 | H14: 0 | I14: 0 | J14: 0 | K14: 0 | L14: 0 | M14: 0 | N14: 0 | O14: 0 | P14: 0 | Q14: 0 | R14: 0 | S14: 0 | T14: 0 | U14: 0 | V14: 0 | W14: 0 | X14: 0 | Y14: 0 | Z14: 0 | AA14: 0 | AB14: 0 | AC14: 0 | AD14: 0 | AE14: 0 | AF14: 0 | AG14: 0 | AH14: 0 | AI14: 0 | AJ14: 0 | AK14: 0 | AL14: 0 | AM14: 0 | AN14: 0 | AO14: 0 | AP14: 0 | AQ14: 0 | AR14: 0 | AS14: 0 | AT14: 0 | AU14: 0 | AV14: 0 | AW14: 0 | AX14: 0
B15: E. Private pension contributions | C15: =Model!E404 -> 0 | D15: =Model!F404 -> 0 | E15: =Model!G404 -> 0 | F15: =Model!H404 -> 0 | G15: =Model!I404 -> 0 | H15: =Model!J404 -> 0 | I15: =Model!K404 -> 0 | J15: =Model!L404 -> 0 | ... AX15: =Model!AZ404 -> 0
B16: F.i. Starting to invest/ investing more - lump sum | C16: =Model!E438 -> 0 | D16: =Model!F438 -> 0 | E16: =Model!G438 -> 0 | F16: =Model!H438 -> 0 | G16: =Model!I438 -> 0 | H16: =Model!J438 -> 0 | I16: =Model!K438 -> 0 | J16: =Model!L438 -> 0 | ... AX16: =Model!AZ438 -> 0
B17: F.ii. Starting to invest/ investing more - ongoing | C17: =Model!E482 -> 21.129031 | D17: =Model!F482 -> 42.258063 | E17: =Model!G482 -> 63.387094 | F17: =Model!H482 -> 84.516126 | G17: =Model!I482 -> 105.64516 | H17: =Model!J482 -> 126.77419 | I17: =Model!K482 -> 147.90322 | J17: =Model!L482 -> 169.03225 | ... AX17: =Model!AZ482 -> 7035.0968
B18: G.i. Adjust investments - lump | C18: =Model!E526 -> 498.22256 | D18: =Model!F526 -> 634.10649 | E18: =Model!G526 -> 791.65251 | F18: =Model!H526 -> 973.83216 | G18: =Model!I526 -> 1183.9989 | H18: =Model!J526 -> 1425.9353 | I18: =Model!K526 -> 1703.9068 | J18: =Model!L526 -> 2022.721 | ... AX18: =Model!AZ526 -> 375734.17
B19: G.ii. Adjust investments - continuous | C19: =Model!E560 -> 122.76435 | D19: =Model!F560 -> 203.42829 | E19: =Model!G560 -> 299.32482 | F19: =Model!H560 -> 412.50708 | G19: =Model!I560 -> 545.27316 | H19: =Model!J560 -> 700.19356 | I19: =Model!K560 -> 880.14174 | J19: =Model!L560 -> 1088.3279 | ... AX19: =Model!AZ560 -> 209340.68
B20: H. Emergency Fund/Child Savings | C20: =Model!E601 -> -1553.6052 | D20: =Model!F601 -> -1553.6052 | E20: =Model!G601 -> -1553.6052 | F20: =Model!H601 -> -1553.6052 | G20: =Model!I601 -> -1553.6052 | H20: =Model!J601 -> -1553.6052 | I20: =Model!K601 -> -1553.6052 | J20: =Model!L601 -> -1553.6052 | ... AX20: =Model!AZ601 -> -1553.6052
B21: F & G levers combined | C21: =sum(C16:C19) -> 642.11594 | D21: =sum(D16:D19) -> 879.79284 | E21: =sum(E16:E19) -> 1154.3644 | F21: =sum(F16:F19) -> 1470.8554 | G21: =sum(G16:G19) -> 1834.9172 | H21: =sum(H16:H19) -> 2252.9031 | I21: =sum(I16:I19) -> 2731.9518 | J21: =sum(J16:J19) -> 3280.0811 | ... AX21: =sum(AX16:AX19) -> 592109.95
B22: Cash flow after dependent levers | C22: =C8+sum(C14:C20) -> 642.11594 | D22: =D8+sum(D14:D20) -> 879.79284 | E22: =E8+sum(E14:E20) -> 1154.3644 | F22: =F8+sum(F14:F20) -> 1470.8554 | G22: =G8+sum(G14:G20) -> 1834.9172 | H22: =H8+sum(H14:H20) -> 2252.9031 | I22: =I8+sum(I14:I20) -> 2731.9518 | J22: =J8+sum(J14:J20) -> 3280.0811 | ... AX22: =AX8+sum(AX14:AX20) -> 691401.9
B23: I. Refinancing High-Interest Debt | C23: N/A | D23: N/A | E23: N/A | F23: N/A | G23: N/A | H23: N/A | I23: N/A | J23: N/A | K23: N/A | L23: N/A | M23: N/A | N23: N/A | O23: N/A | P23: N/A | Q23: N/A | R23: N/A | S23: N/A | T23: N/A | U23: N/A | V23: N/A | W23: N/A | X23: N/A | Y23: N/A | Z23: N/A | AA23: N/A | AB23: N/A | AC23: N/A | AD23: N/A | AE23: N/A | AF23: N/A | AG23: N/A | AH23: N/A | AI23: N/A | AJ23: N/A | AK23: N/A | AL23: N/A | AM23: N/A | AN23: N/A | AO23: N/A | AP23: N/A | AQ23: N/A | AR23: N/A | AS23: N/A | AT23: N/A | AU23: N/A | AV23: N/A | AW23: N/A | AX23: N/A
B24: J. Consolidating or Paying Off Debt Faster | C24: N/A | D24: N/A | E24: N/A | F24: N/A | G24: N/A | H24: N/A | I24: N/A | J24: N/A | K24: N/A | L24: N/A | M24: N/A | N24: N/A | O24: N/A | P24: N/A | Q24: N/A | R24: N/A | S24: N/A | T24: N/A | U24: N/A | V24: N/A | W24: N/A | X24: N/A | Y24: N/A | Z24: N/A | AA24: N/A | AB24: N/A | AC24: N/A | AD24: N/A | AE24: N/A | AF24: N/A | AG24: N/A | AH24: N/A | AI24: N/A | AJ24: N/A | AK24: N/A | AL24: N/A | AM24: N/A | AN24: N/A | AO24: N/A | AP24: N/A | AQ24: N/A | AR24: N/A | AS24: N/A | AT24: N/A | AU24: N/A | AV24: N/A | AW24: N/A | AX24: N/A
B28: Net wealth trajectory
C30: =C3 -> 46143 | D30: =D3 -> 46508 | E30: =E3 -> 46874 | F30: =F3 -> 47239 | G30: =G3 -> 47604 | H30: =H3 -> 47969 | I30: =I3 -> 48335 | J30: =J3 -> 48700 | ... AX30: =AX3 -> 63310
B31: 0. Do-Nothing (Baseline) | C31: =Model!E58 -> -89181.923 | D31: =Model!F58 -> 823.04387 | E31: =Model!G58 -> 92378.294 | F31: =Model!H58 -> 185576.5 | G31: =Model!I58 -> 280516.71 | H31: =Model!J58 -> 377304.8 | I31: =Model!K58 -> 476053.94 | J31: =Model!L58 -> 576885.16 | ... AX31: =Model!AZ58 -> 8565481.7
B32: =Model!B119 -> Meet Financial Goal: Purchasing NE London Property | C32: =Model!E153 -> -22959.258 | D32: =Model!F153 -> -18891.07 | E32: =Model!G153 -> -13733.251 | F32: =Model!H153 -> -7445.5981 | G32: =Model!I153 -> 13.600143 | H32: =Model!J153 -> 8687.6231 | I32: =Model!K153 -> 18621.378 | J32: =Model!L153 -> 29861.463 | ... AX32: =Model!AZ153 -> 2001385.6
B33: =Model!B167 -> Meet Financial Goal: Short Term Expenses | C33: =Model!E191 -> -15800 | D33: =Model!F191 -> -15800 | E33: =Model!G191 -> -15800 | F33: =Model!H191 -> -15800 | G33: =Model!I191 -> -15800 | H33: =Model!J191 -> -15800 | I33: =Model!K191 -> -15800 | J33: =Model!L191 -> -15800 | ... AX33: =Model!AZ191 -> -15800
B34: =Model!B204 -> Meet Financial Goal: Comfortable Retirement | C34: =Model!E230 -> 459.46185 | D34: =Model!F230 -> 16707.565 | E34: =Model!G230 -> 33443.11 | F34: =Model!H230 -> 50680.722 | G34: =Model!I230 -> 68435.463 | H34: =Model!J230 -> 86722.846 | I34: =Model!K230 -> 105558.85 | J34: =Model!L230 -> 124959.93 | ... AX34: =Model!AZ230 -> 692260.75
B35: Meeting goals net wealth | C35: =sum(C31:C34) -> -127481.72 | D35: =sum(D31:D34) -> -17160.462 | E35: =sum(E31:E34) -> 96288.154 | F35: =sum(F31:F34) -> 213011.63 | G35: =sum(G31:G34) -> 333165.77 | H35: =sum(H31:H34) -> 456915.27 | I35: =sum(I31:I34) -> 584434.17 | J35: =sum(J31:J34) -> 715906.55 | ... AX35: =sum(AX31:AX34) -> 11243328
B36: A. Increasing Salary | C36: =Model!E267 -> 2160 | D36: =Model!F267 -> 4363.2 | E36: =Model!G267 -> 6610.464 | F36: =Model!H267 -> 8902.6733 | G36: =Model!I267 -> 11240.727 | H36: =Model!J267 -> 13625.541 | I36: =Model!K267 -> 16058.052 | J36: =Model!L267 -> 18539.213 | ... AX36: =Model!AZ267 -> 0
B37: B. Side hustles and additional income streams | C37: =0 -> 0 | D37: =0 -> 0 | E37: =0 -> 0 | F37: =0 -> 0 | G37: =0 -> 0 | H37: =0 -> 0 | I37: =0 -> 0 | J37: =0 -> 0 | ... AX37: =0 -> 0
B38: C. Reducing Fixed Expenses | C38: =Model!E330 -> 2070 | D38: =Model!F330 -> 4140 | E38: =Model!G330 -> 6210 | F38: =Model!H330 -> 8280 | G38: =Model!I330 -> 10350 | H38: =Model!J330 -> 12420 | I38: =Model!K330 -> 14490 | J38: =Model!L330 -> 16560 | ... AX38: =Model!AZ330 -> 99360
B39: Independent levers net wealth | C39: =sum(C35:C38) -> -123251.72 | D39: =sum(D35:D38) -> -8657.262 | E39: =sum(E35:E38) -> 109108.62 | F39: =sum(F35:F38) -> 230194.3 | G39: =sum(G35:G38) -> 354756.5 | H39: =sum(H35:H38) -> 482960.81 | I39: =sum(I35:I38) -> 614982.22 | J39: =sum(J35:J38) -> 751005.77 | ... AX39: =sum(AX35:AX38) -> 11342688
B40: D. Higher-yield savings | C40: =Model!E359 -> 0 | D40: =Model!F359 -> 54.376184 | E40: =Model!G359 -> 165.03172 | F40: =Model!H359 -> 333.93638 | G40: =Model!I359 -> 563.12889 | H40: =Model!J359 -> 854.71932 | I40: =Model!K359 -> 1210.8916 | J40: =Model!L359 -> 1633.9061 | ... AX40: =Model!AZ359 -> 736507.71
B41: E. Private pension contributions | C41: =Model!E405 -> 0 | D41: =Model!F405 -> 0 | E41: =Model!G405 -> 0 | F41: =Model!H405 -> 0 | G41: =Model!I405 -> 0 | H41: =Model!J405 -> 0 | I41: =Model!K405 -> 0 | J41: =Model!L405 -> 0 | ... AX41: =Model!AZ405 -> 0
B42: F.i. Investing - lump sum | C42: =Model!E446 -> 0 | D42: =Model!F446 -> 0 | E42: =Model!G446 -> 0 | F42: =Model!H446 -> 0 | G42: =Model!I446 -> 0 | H42: =Model!J446 -> 0 | I42: =Model!K446 -> 0 | J42: =Model!L446 -> 0 | ... AX42: =Model!AZ446 -> 0
B43: F.ii. Investing - ongoing | C43: =Model!E491 -> 21.129031 | D43: =Model!F491 -> 174.78059 | E43: =Model!G491 -> 468.94159 | F43: =Model!H491 -> 912.17161 | G43: =Model!I491 -> 1513.6439 | H43: =Model!J491 -> 2283.1896 | I43: =Model!K491 -> 3231.3445 | J43: =Model!L491 -> 4369.4 | ... AX43: =Model!AZ491 -> 1261179.5
B44: G.i. Adjust investments - lump | C44: =Model!E537 -> 3831.3426 | D44: =Model!F537 -> 9995.8862 | E44: =Model!G537 -> 17303.318 | F44: =Model!H537 -> 25918.989 | G44: =Model!I537 -> 36030.032 | H44: =Model!J537 -> 47848.102 | I44: =Model!K537 -> 61612.459 | J44: =Model!L537 -> 77593.424 | ... AX44: =Model!AZ537 -> 21434691
B45: G.ii. Adjust investments - continuous | C45: =Model!E571 -> 572.76435 | D45: =Model!F571 -> 1631.4583 | E45: =Model!G571 -> 3321.6939 | F45: =Model!H571 -> 5745.2605 | G45: =Model!I571 -> 9016.9929 | H45: =Model!J571 -> 13266.29 | I45: =Model!K571 -> 18638.806 | J45: =Model!L571 -> 25298.32 | ... AX45: =Model!AZ571 -> 11023278
...

Sheet Graphs
B2: {=Summary!A3:AZ7} | D2: 46143 | E2: 46508 | F2: 46874 | G2: 47239 | H2: 47604 | I2: 47969 | J2: 48335 | K2: 48700 | L2: 49065 | M2: 49430 | N2: 49796 | O2: 50161 | P2: 50526 | Q2: 50891 | R2: 51257 | S2: 51622 | T2: 51987 | U2: 52352 | V2: 52718 | W2: 53083 | X2: 53448 | Y2: 53813 | Z2: 54179 | AA2: 54544 | AB2: 54909 | AC2: 55274 | AD2: 55640 | AE2: 56005 | AF2: 56370 | AG2: 56735 | AH2: 57101 | AI2: 57466 | AJ2: 57831 | AK2: 58196 | AL2: 58562 | AM2: 58927 | AN2: 59292 | AO2: 59657 | AP2: 60023 | AQ2: 60388 | AR2: 60753 | AS2: 61118 | AT2: 61484 | AU2: 61849 | AV2: 62214 | AW2: 62579 | AX2: 62945 | AY2: 63310
C3: Do-Nothing (Baseline) | D3: 50845.56 | E3: 50845.56 | F3: 50845.56 | G3: 50845.56 | H3: 50845.56 | I3: 50845.56 | J3: 50845.56 | K3: 50845.56 | L3: 50845.56 | M3: 50845.56 | N3: 50845.56 | O3: 50845.56 | P3: 50845.56 | Q3: 50845.56 | R3: 50845.56 | S3: 50845.56 | T3: 50845.56 | U3: 50845.56 | V3: 50845.56 | W3: 50845.56 | X3: 50845.56 | Y3: 50845.56 | Z3: 50845.56 | AA3: 50845.56 | AB3: 50845.56 | AC3: 50845.56 | AD3: 50845.56 | AE3: 50845.56 | AF3: 50845.56 | AG3: 50845.56 | AH3: 50845.56 | AI3: 50845.56 | AJ3: 50845.56 | AK3: 50845.56 | AL3: 50845.56 | AM3: 50845.56 | AN3: 50845.56 | AO3: 50845.56 | AP3: 50845.56 | AQ3: 50845.56 | AR3: 50845.56 | AS3: 50845.56 | AT3: 50845.56 | AU3: 50845.56 | AV3: 50845.56 | AW3: 50845.56 | AX3: 50845.56 | AY3: 50845.56
C4: Meet Financial Goal: Purchasing NE London Property | D4: -33976.56 | E4: -33976.56 | F4: -33976.56 | G4: -33976.56 | H4: -33976.56 | I4: -33976.56 | J4: -33976.56 | K4: -33976.56 | L4: -33976.56 | M4: -33976.56 | N4: -33976.56 | O4: -33976.56 | P4: -33976.56 | Q4: -33976.56 | R4: -33976.56 | S4: -33976.56 | T4: -33976.56 | U4: -33976.56 | V4: -33976.56 | W4: -33976.56 | X4: -33976.56 | Y4: -33976.56 | Z4: -33976.56 | AA4: -33976.56 | AB4: -8000 | AC4: 0 | AD4: 0 | AE4: 0 | AF4: 0 | AG4: 0 | AH4: 0 | AI4: 0 | AJ4: 0 | AK4: 0 | AL4: 0 | AM4: 0 | AN4: 0 | AO4: 0 | AP4: 0 | AQ4: 0 | AR4: 0 | AS4: 0 | AT4: 0 | AU4: 0 | AV4: 0 | AW4: 0 | AX4: 0 | AY4: 0
C5: Meet Financial Goal: Short Term Expenses | D5: 0 | E5: 0 | F5: 0 | G5: 0 | H5: 0 | I5: 0 | J5: 0 | K5: 0 | L5: 0 | M5: 0 | N5: 0 | O5: 0 | P5: 0 | Q5: 0 | R5: 0 | S5: 0 | T5: 0 | U5: 0 | V5: 0 | W5: 0 | X5: 0 | Y5: 0 | Z5: 0 | AA5: 0 | AB5: 0 | AC5: 0 | AD5: 0 | AE5: 0 | AF5: 0 | AG5: 0 | AH5: 0 | AI5: 0 | AJ5: 0 | AK5: 0 | AL5: 0 | AM5: 0 | AN5: 0 | AO5: 0 | AP5: 0 | AQ5: 0 | AR5: 0 | AS5: 0 | AT5: 0 | AU5: 0 | AV5: 0 | AW5: 0 | AX5: 0 | AY5: 0
C6: Meet Financial Goal: Comfortable Retirement | D6: -15315.395 | E6: -15315.395 | F6: -15315.395 | G6: -15315.395 | H6: -15315.395 | I6: -15315.395 | J6: -15315.395 | K6: -15315.395 | L6: -15315.395 | M6: -15315.395 | N6: -15315.395 | O6: -15315.395 | P6: -15315.395 | Q6: -15315.395 | R6: -15315.395 | S6: -15315.395 | T6: -15315.395 | U6: -15315.395 | V6: -15315.395 | W6: -15315.395 | X6: -15315.395 | Y6: -15315.395 | Z6: -15315.395 | AA6: -15315.395 | AB6: -15315.395 | AC6: -15315.395 | AD6: -15315.395 | AE6: -15315.395 | AF6: -15315.395 | AG6: -15315.395 | AH6: -15315.395 | AI6: -15315.395 | AJ6: -15315.395 | AK6: -15315.395 | AL6: -15315.395 | AM6: 50000 | AN6: 50000 | AO6: 50000 | AP6: 50000 | AQ6: 50000 | AR6: 50000 | AS6: 50000 | AT6: 50000 | AU6: 50000 | AV6: 50000 | AW6: 50000 | AX6: 50000 | AY6: 50000
A37: Net Wealth Projections financial goals
B40: 46023 | C40: 46388 | D40: 46753 | E40: 47119 | F40: 47484 | G40: 47849 | H40: 48214 | I40: 48580 | J40: 48945 | K40: 49310 | L40: 49675 | M40: 50041 | N40: 50406 | O40: 50771 | P40: 51136 | Q40: 51502 | R40: 51867 | S40: 52232 | T40: 52597 | U40: 52963
A41: "Do-nothing" | B41: =Summary!C31 -> -89181.923 | C41: =Summary!D31 -> 823.04387 | D41: =Summary!E31 -> 92378.294 | E41: =Summary!F31 -> 185576.5 | F41: =Summary!G31 -> 280516.71 | G41: =Summary!H31 -> 377304.8 | H41: =Summary!I31 -> 476053.94 | I41: =Summary!J31 -> 576885.16 | ... U41: =Summary!V31 -> 1851826.4
A42: Financial Goals | B42: =Summary!C35 -> -127481.72 | C42: =Summary!D35 -> -17160.462 | D42: =Summary!E35 -> 96288.154 | E42: =Summary!F35 -> 213011.63 | F42: =Summary!G35 -> 333165.77 | G42: =Summary!H35 -> 456915.27 | H42: =Summary!I35 -> 584434.17 | I42: =Summary!J35 -> 715906.55 | ... U42: =Summary!V35 -> 2530796.7
A70: Lever A-C Net Income Increase
C71: 46143 | D71: 46508 | E71: 46874 | F71: 47239 | G71: 47604 | H71: 47969 | I71: 48335 | J71: 48700 | K71: 49065 | L71: 49430 | M71: 49796 | N71: 50161 | O71: 50526 | P71: 50891 | Q71: 51257 | R71: 51622 | S71: 51987 | T71: 52352 | U71: 52718 | V71: 53083 | W71: 53448 | X71: 53813 | Y71: 54179 | Z71: 54544 | AA71: 54909 | AB71: 55274 | AC71: 55640 | AD71: 56005 | AE71: 56370 | AF71: 56735 | AG71: 57101 | AH71: 57466 | AI71: 57831 | AJ71: 58196 | AK71: 58562 | AL71: 58927
B72: Increasing Salary | C72: =Summary!C9 -> 2160 | D72: =Summary!D9 -> 2203.2 | E72: =Summary!E9 -> 2247.264 | F72: =Summary!F9 -> 2292.2093 | G72: =Summary!G9 -> 2338.0535 | H72: =Summary!H9 -> 2384.8145 | I72: =Summary!I9 -> 2432.5108 | J72: =Summary!J9 -> 2481.161 | ... AL72: =Summary!AL9 -> 4319.7614
B73: Reducing Fixed Expenses | C73: =Summary!C11 -> 2070 | D73: =Summary!D11 -> 2070 | E73: =Summary!E11 -> 2070 | F73: =Summary!F11 -> 2070 | G73: =Summary!G11 -> 2070 | H73: =Summary!H11 -> 2070 | I73: =Summary!I11 -> 2070 | J73: =Summary!J11 -> 2070 | ... AL73: =Summary!AL11 -> 2070
A98: Net Wealth Projections Levers A-C
B101: 46023 | C101: 46388 | D101: 46753 | E101: 47119 | F101: 47484 | G101: 47849 | H101: 48214 | I101: 48580 | J101: 48945 | K101: 49310 | L101: 49675 | M101: 50041 | N101: 50406 | O101: 50771 | P101: 51136 | Q101: 51502 | R101: 51867 | S101: 52232 | T101: 52597 | U101: 52963
A102: "Do-nothing" | B102: =Summary!C31 -> -89181.923 | C102: =Summary!D31 -> 823.04387 | D102: =Summary!E31 -> 92378.294 | E102: =Summary!F31 -> 185576.5 | F102: =Summary!G31 -> 280516.71 | G102: =Summary!H31 -> 377304.8 | H102: =Summary!I31 -> 476053.94 | I102: =Summary!J31 -> 576885.16 | ... U102: =Summary!V31 -> 1851826.4
A103: Levers A & C | B103: =sum(Summary!C36:C38)+B102 -> -84951.923 | C103: =sum(Summary!D36:D38)+C102 -> 9326.2439 | D103: =sum(Summary!E36:E38)+D102 -> 105198.76 | E103: =sum(Summary!F36:F38)+E102 -> 202759.17 | F103: =sum(Summary!G36:G38)+F102 -> 302107.44 | G103: =sum(Summary!H36:H38)+G102 -> 403350.34 | H103: =sum(Summary!I36:I38)+H102 -> 506601.99 | I103: =sum(Summary!J36:J38)+I102 -> 611984.37 | ... U103: =sum(Summary!V36:V38)+U102 -> 1945708.7
C131: Lever D - H Prioritized by Net Income Impact | D131: £ 5 years (2030) | E131: % | F131: £ 20 years (2045) | G131: %
C132: G.i. Adjust investments - one-time | D132: =Summary!G18 -> 1183.9989 | E132: =D132/Summary!G$4 -> 0.02328618 | F132: =Summary!V18 -> 11895.482 | G132: =F132/Summary!V$4 -> 0.23395321
C133: G.ii. Adjust investments - ongoing | D133: =Summary!G19 -> 545.27316 | E133: =D133/Summary!G$4 -> 0.010724106 | F133: =Summary!V19 -> 7618.5575 | G133: =F133/Summary!V$4 -> 0.14983722
C134: F.ii. Starting to invest/ investing more - ongoing | D134: =Summary!G17 -> 105.64516 | E134: =D134/Summary!G$4 -> 0.0020777656 | F134: =Summary!V17 -> 422.58063 | G134: =F134/Summary!V$4 -> 0.0083110625
C135: F.i. Starting to invest/ investing more - one-time | D135: =Summary!G16 -> 0 | E135: =D135/Summary!G$4 -> 0 | F135: =Summary!V16 -> 0 | G135: =F135/Summary!V$4 -> 0
C136: D. Investing in higher-yield savings | D136: =Summary!G14 -> 0 | E136: =D136/Summary!G$4 -> 0 | F136: =Summary!V14 -> 0 | G136: =F136/Summary!V$4 -> 0
C137: E. Private pension contributions | D137: =Summary!G15 -> 0 | E137: =D137/Summary!G$4 -> 0 | F137: =Summary!V15 -> 0 | G137: =F137/Summary!V$4 -> 0
C138: H. Emergency fund/child savings | D138: =Summary!G20 -> -1553.6052 | E138: =D138/Summary!G$4 -> -0.030555377 | F138: =Summary!V20 -> -1553.6052 | G138: =F138/Summary!V$4 -> -0.030555377
C142: Lever D - H Prioritized by Net Wealth Impact | D142: £ 5 years (2030) | E142: % | F142: £ 20 years (2045) | G142: %
C143: G.i. Adjust investments - one-time | D143: =Summary!G44 -> 36030.032 | E143: =D143/Summary!G$31 -> 0.12844166 | F143: =Summary!V44 -> 604577.3 | G143: =F143/Summary!V$31 -> 0.32647622
C144: G.ii. Adjust investments - ongoing | D144: =Summary!G45 -> 9016.9929 | E144: =D144/Summary!G$31 -> 0.032144227 | F144: =Summary!V45 -> 301198.19 | G144: =F144/Summary!V$31 -> 0.16264926
C145: F.ii. Starting to invest/ investing more - ongoing | D145: =Summary!G43 -> 1513.6439 | E145: =D145/Summary!G$31 -> 0.0053959136 | F145: =Summary!V43 -> 38250.657 | G145: =F145/Summary!V$31 -> 0.020655638
C146: H. Emergency fund/child savings | D146: =Summary!G46 -> 563.12889 | E146: =D146/Summary!G$31 -> 0.00200747 | F146: =Summary!V46 -> 12863.357 | G146: =F146/Summary!V$31 -> 0.0069463082
C147: D. Investing in higher-yield savings | D147: =Summary!G40 -> 563.12889 | E147: =D147/Summary!G$31 -> 0.00200747 | F147: =Summary!V40 -> 12863.357 | G147: =F147/Summary!V$31 -> 0.0069463082
C148: F.i. Starting to invest/ investing more - one-time | D148: =Summary!G42 -> 0 | E148: =D148/Summary!G$31 -> 0 | F148: =Summary!V42 -> 0 | G148: =F148/Summary!V$31 -> 0
C149: E. Private pension contributions | D149: =Summary!G41 -> 0 | E149: =D149/Summary!G$31 -> 0 | F149: =Summary!V41 -> 0 | G149: =F149/Summary!V$31 -> 0

Sheet Questions
A1: Do you have any checking or savings accounts? None have currently been provided
A2: When you say sister is buying you out of home, does this entail she is taking over the mortgage as well?
A3: What share of the downpayment will be coming out of your investments?
A4: Are mortgage payments going to be split 50/50 with your sister?
A5: You mentioned that you are paying 817 for mortgage. Is this in addition to the mortgage monthly payments of 2220.87?
